<?xml version="1.0" encoding="UTF-8"?>
<testng-results skipped="0" failed="1" total="1" passed="0">
  <reporter-output>
  </reporter-output>
  <suite name="Default suite" duration-ms="10450" started-at="2018-07-19T12:35:30Z" finished-at="2018-07-19T12:35:40Z">
    <groups>
    </groups>
    <test name="Default test" duration-ms="10450" started-at="2018-07-19T12:35:30Z" finished-at="2018-07-19T12:35:40Z">
      <class name="testCases.MainTest2">
        <test-method status="PASS" signature="beforeSuit()[pri:0, instance:testCases.MainTest2@1a5f880]" name="beforeSuit" is-config="true" duration-ms="405" started-at="2018-07-19T18:05:29Z" finished-at="2018-07-19T18:05:30Z">
          <reporter-output>
          </reporter-output>
        </test-method> <!-- beforeSuit -->
        <test-method status="PASS" signature="start()[pri:0, instance:testCases.MainTest2@1a5f880]" name="start" is-config="true" duration-ms="8165" started-at="2018-07-19T18:05:30Z" finished-at="2018-07-19T18:05:38Z">
          <reporter-output>
          </reporter-output>
        </test-method> <!-- start -->
        <test-method status="PASS" signature="setup(java.lang.reflect.Method)[pri:0, instance:testCases.MainTest2@1a5f880]" name="setup" is-config="true" duration-ms="9" started-at="2018-07-19T18:05:38Z" finished-at="2018-07-19T18:05:38Z">
          <params>
            <param index="0">
              <value>
                <![CDATA[public void testCases.MainTest2.Login() throws java.lang.Exception]]>
              </value>
            </param>
          </params>
          <reporter-output>
          </reporter-output>
        </test-method> <!-- setup -->
        <test-method status="FAIL" signature="Login()[pri:0, instance:testCases.MainTest2@1a5f880]" name="Login" duration-ms="1840" started-at="2018-07-19T18:05:38Z" finished-at="2018-07-19T18:05:40Z">
          <exception class="java.lang.AssertionError">
            <message>
              <![CDATA[expected [emotl] but found [Demotl]]]>
            </message>
            <full-stacktrace>
              <![CDATA[java.lang.AssertionError: expected [emotl] but found [Demotl]
	at org.testng.Assert.fail(Assert.java:94)
	at org.testng.Assert.failNotEquals(Assert.java:494)
	at org.testng.Assert.assertEquals(Assert.java:123)
	at org.testng.Assert.assertEquals(Assert.java:176)
	at org.testng.Assert.assertEquals(Assert.java:186)
	at testCases.MainTest2.Login(MainTest2.java:87)
	at sun.reflect.NativeMethodAccessorImpl.invoke0(Native Method)
	at sun.reflect.NativeMethodAccessorImpl.invoke(Unknown Source)
	at sun.reflect.DelegatingMethodAccessorImpl.invoke(Unknown Source)
	at java.lang.reflect.Method.invoke(Unknown Source)
	at org.testng.internal.MethodInvocationHelper.invokeMethod(MethodInvocationHelper.java:80)
	at org.testng.internal.Invoker.invokeMethod(Invoker.java:714)
	at org.testng.internal.Invoker.invokeTestMethod(Invoker.java:901)
	at org.testng.internal.Invoker.invokeTestMethods(Invoker.java:1231)
	at org.testng.internal.TestMethodWorker.invokeTestMethods(TestMethodWorker.java:127)
	at org.testng.internal.TestMethodWorker.run(TestMethodWorker.java:111)
	at org.testng.TestRunner.privateRun(TestRunner.java:767)
	at org.testng.TestRunner.run(TestRunner.java:617)
	at org.testng.SuiteRunner.runTest(SuiteRunner.java:334)
	at org.testng.SuiteRunner.runSequentially(SuiteRunner.java:329)
	at org.testng.SuiteRunner.privateRun(SuiteRunner.java:291)
	at org.testng.SuiteRunner.run(SuiteRunner.java:240)
	at org.testng.SuiteRunnerWorker.runSuite(SuiteRunnerWorker.java:52)
	at org.testng.SuiteRunnerWorker.run(SuiteRunnerWorker.java:86)
	at org.testng.TestNG.runSuitesSequentially(TestNG.java:1198)
	at org.testng.TestNG.runSuitesLocally(TestNG.java:1123)
	at org.testng.TestNG.run(TestNG.java:1031)
	at org.testng.remote.AbstractRemoteTestNG.run(AbstractRemoteTestNG.java:114)
	at org.testng.remote.RemoteTestNG.initAndRun(RemoteTestNG.java:251)
	at org.testng.remote.RemoteTestNG.main(RemoteTestNG.java:77)
]]>
            </full-stacktrace>
          </exception> <!-- java.lang.AssertionError -->
          <reporter-output>
          </reporter-output>
        </test-method> <!-- Login -->
        <test-method status="PASS" signature="tearDown(org.testng.ITestResult, java.lang.reflect.Method)[pri:0, instance:testCases.MainTest2@1a5f880]" name="tearDown" is-config="true" duration-ms="341" started-at="2018-07-19T18:05:40Z" finished-at="2018-07-19T18:05:40Z">
          <params>
            <param index="0">
              <value>
                <![CDATA[[TestResult name=Login status=FAILURE method=MainTest2.Login()[pri:0, instance:testCases.MainTest2@1a5f880] output={null}]]]>
              </value>
            </param>
            <param index="1">
              <value>
                <![CDATA[public void testCases.MainTest2.Login() throws java.lang.Exception]]>
              </value>
            </param>
          </params>
          <reporter-output>
          </reporter-output>
        </test-method> <!-- tearDown -->
        <test-method status="PASS" signature="teardown()[pri:0, instance:testCases.MainTest2@1a5f880]" name="teardown" is-config="true" duration-ms="72" started-at="2018-07-19T18:05:40Z" finished-at="2018-07-19T18:05:40Z">
          <reporter-output>
          </reporter-output>
        </test-method> <!-- teardown -->
        <test-method status="PASS" signature="afterSuite()[pri:0, instance:testCases.MainTest2@1a5f880]" name="afterSuite" is-config="true" duration-ms="962" started-at="2018-07-19T18:05:40Z" finished-at="2018-07-19T18:05:41Z">
          <reporter-output>
          </reporter-output>
        </test-method> <!-- afterSuite -->
      </class> <!-- testCases.MainTest2 -->
    </test> <!-- Default test -->
  </suite> <!-- Default suite -->
</testng-results>
