<?xml version="1.0" encoding="UTF-8"?>
<testng-results skipped="0" failed="1" total="1" passed="0">
  <reporter-output>
  </reporter-output>
  <suite name="Default suite" duration-ms="9325" started-at="2018-06-19T06:49:34Z" finished-at="2018-06-19T06:49:43Z">
    <groups>
    </groups>
    <test name="Default test" duration-ms="9325" started-at="2018-06-19T06:49:34Z" finished-at="2018-06-19T06:49:43Z">
      <class name="userLogin.MainTest">
        <test-method status="PASS" signature="beforeSuit()[pri:0, instance:userLogin.MainTest@70fda8]" name="beforeSuit" is-config="true" duration-ms="140" started-at="2018-06-19T12:19:33Z" finished-at="2018-06-19T12:19:34Z">
          <reporter-output>
          </reporter-output>
        </test-method> <!-- beforeSuit -->
        <test-method status="PASS" signature="start()[pri:0, instance:userLogin.MainTest@70fda8]" name="start" is-config="true" duration-ms="6858" started-at="2018-06-19T12:19:34Z" finished-at="2018-06-19T12:19:40Z">
          <reporter-output>
          </reporter-output>
        </test-method> <!-- start -->
        <test-method status="PASS" signature="setup(java.lang.reflect.Method)[pri:0, instance:userLogin.MainTest@70fda8]" name="setup" is-config="true" duration-ms="12" started-at="2018-06-19T12:19:41Z" finished-at="2018-06-19T12:19:41Z">
          <params>
            <param index="0">
              <value>
                <![CDATA[public void userLogin.MainTest.Login() throws java.lang.Exception]]>
              </value>
            </param>
          </params>
          <reporter-output>
          </reporter-output>
        </test-method> <!-- setup -->
        <test-method status="FAIL" signature="Login()[pri:0, instance:userLogin.MainTest@70fda8]" name="Login" duration-ms="2068" started-at="2018-06-19T12:19:41Z" finished-at="2018-06-19T12:19:43Z">
          <exception class="java.lang.AssertionError">
            <message>
              <![CDATA[expected [Deotl] but found [Demotl]]]>
            </message>
            <full-stacktrace>
              <![CDATA[java.lang.AssertionError: expected [Deotl] but found [Demotl]
	at org.testng.Assert.fail(Assert.java:94)
	at org.testng.Assert.failNotEquals(Assert.java:494)
	at org.testng.Assert.assertEquals(Assert.java:123)
	at org.testng.Assert.assertEquals(Assert.java:176)
	at org.testng.Assert.assertEquals(Assert.java:186)
	at userLogin.MainTest.Login(MainTest.java:67)
	at sun.reflect.NativeMethodAccessorImpl.invoke0(Native Method)
	at sun.reflect.NativeMethodAccessorImpl.invoke(Unknown Source)
	at sun.reflect.DelegatingMethodAccessorImpl.invoke(Unknown Source)
	at java.lang.reflect.Method.invoke(Unknown Source)
	at org.testng.internal.MethodInvocationHelper.invokeMethod(MethodInvocationHelper.java:80)
	at org.testng.internal.Invoker.invokeMethod(Invoker.java:714)
	at org.testng.internal.Invoker.invokeTestMethod(Invoker.java:901)
	at org.testng.internal.Invoker.invokeTestMethods(Invoker.java:1231)
	at org.testng.internal.TestMethodWorker.invokeTestMethods(TestMethodWorker.java:127)
	at org.testng.internal.TestMethodWorker.run(TestMethodWorker.java:111)
	at org.testng.TestRunner.privateRun(TestRunner.java:767)
	at org.testng.TestRunner.run(TestRunner.java:617)
	at org.testng.SuiteRunner.runTest(SuiteRunner.java:334)
	at org.testng.SuiteRunner.runSequentially(SuiteRunner.java:329)
	at org.testng.SuiteRunner.privateRun(SuiteRunner.java:291)
	at org.testng.SuiteRunner.run(SuiteRunner.java:240)
	at org.testng.SuiteRunnerWorker.runSuite(SuiteRunnerWorker.java:52)
	at org.testng.SuiteRunnerWorker.run(SuiteRunnerWorker.java:86)
	at org.testng.TestNG.runSuitesSequentially(TestNG.java:1198)
	at org.testng.TestNG.runSuitesLocally(TestNG.java:1123)
	at org.testng.TestNG.run(TestNG.java:1031)
	at org.testng.remote.AbstractRemoteTestNG.run(AbstractRemoteTestNG.java:114)
	at org.testng.remote.RemoteTestNG.initAndRun(RemoteTestNG.java:251)
	at org.testng.remote.RemoteTestNG.main(RemoteTestNG.java:77)
]]>
            </full-stacktrace>
          </exception> <!-- java.lang.AssertionError -->
          <reporter-output>
          </reporter-output>
        </test-method> <!-- Login -->
        <test-method status="PASS" signature="tearDown(org.testng.ITestResult, java.lang.reflect.Method)[pri:0, instance:userLogin.MainTest@70fda8]" name="tearDown" is-config="true" duration-ms="378" started-at="2018-06-19T12:19:43Z" finished-at="2018-06-19T12:19:43Z">
          <params>
            <param index="0">
              <value>
                <![CDATA[[TestResult name=Login status=FAILURE method=MainTest.Login()[pri:0, instance:userLogin.MainTest@70fda8] output={null}]]]>
              </value>
            </param>
            <param index="1">
              <value>
                <![CDATA[public void userLogin.MainTest.Login() throws java.lang.Exception]]>
              </value>
            </param>
          </params>
          <reporter-output>
          </reporter-output>
        </test-method> <!-- tearDown -->
        <test-method status="PASS" signature="teardown()[pri:0, instance:userLogin.MainTest@70fda8]" name="teardown" is-config="true" duration-ms="0" started-at="2018-06-19T12:19:43Z" finished-at="2018-06-19T12:19:43Z">
          <reporter-output>
          </reporter-output>
        </test-method> <!-- teardown -->
        <test-method status="PASS" signature="afterSuite()[pri:0, instance:userLogin.MainTest@70fda8]" name="afterSuite" is-config="true" duration-ms="250" started-at="2018-06-19T12:19:43Z" finished-at="2018-06-19T12:19:43Z">
          <reporter-output>
          </reporter-output>
        </test-method> <!-- afterSuite -->
      </class> <!-- userLogin.MainTest -->
    </test> <!-- Default test -->
  </suite> <!-- Default suite -->
</testng-results>
